#VRML_SIM R2021b utf8
WorldInfo {
  coordinateSystem "NUE"
}
Viewpoint {
  orientation -0.35080068679819378 -0.903171124582505 -0.29902121830453876 1.66314778904074
  position -2.67438143304056 1.882223242162395 -0.6345773505503721
}
TexturedBackground {
}
TexturedBackgroundLight {
}
RectangleArena {
  floorSize 3 3
}
Solid {
  translation -0.25 0 -0.75
  children [
    Shape {
      appearance PBRAppearance {
      }
      geometry Box {
        size 0.35 0.25 0.35
      }
    }
  ]
}
Solid {
  translation -0.75 0 -0.25
  children [
    Shape {
      appearance PBRAppearance {
      }
      geometry Box {
        size 0.35 0.25 0.35
      }
    }
  ]
  name "solid(2)"
}
Solid {
  translation 0.25 0 0.25
  children [
    Shape {
      appearance PBRAppearance {
      }
      geometry Box {
        size 0.35 0.25 0.35
      }
    }
  ]
  name "solid(4)"
}
Solid {
  translation 0.75 0 0.25
  children [
    Shape {
      appearance PBRAppearance {
      }
      geometry Box {
        size 0.35 0.25 0.35
      }
    }
  ]
  name "solid(5)"
}
Solid {
  translation 1.25 0 -0.75
  children [
    Shape {
      appearance PBRAppearance {
      }
      geometry Box {
        size 0.35 0.25 0.35
      }
    }
  ]
  name "solid(6)"
}
Solid {
  translation -0.35 0 1.25
  children [
    Shape {
      appearance PBRAppearance {
      }
      geometry Box {
        size 0.35 0.25 0.35
      }
    }
  ]
  name "solid(7)"
}
Solid {
  translation -1 0 0.75
  children [
    Shape {
      appearance PBRAppearance {
      }
      geometry Box {
        size 0.35 0.25 0.35
      }
    }
  ]
  name "solid(8)"
}
DEF DiffDriveRobotWithEyes Robot {
  children [
    DEF BodyShapeWithTransform Transform {
      translation -1.28 0.0665 -1.28
      children [
        DEF Body Shape {
          appearance PBRAppearance {
            baseColor 1 0 0
            roughness 1
            metalness 0
          }
          geometry Cylinder {
            height 0.08
            radius 0.045
          }
        }
      ]
    }
    DEF wheel_joint HingeJoint {
      jointParameters HingeJointParameters {
        anchor -1.325 0.025 -1.28
      }
      device [
        PositionSensor {
          name "leftEncoder"
        }
        RotationalMotor {
          name "motor_1"
        }
      ]
      endPoint Solid {
        translation -1.325 0.025 -1.28
        rotation 1.9633974819787822e-15 -6.754087338007011e-15 1 1.5699999999999619
        children [
          DEF shape_wheel Shape {
            appearance PBRAppearance {
              baseColor 0 0 1
              roughness 1
              metalness 0
            }
            geometry Cylinder {
              height 0.01
              radius 0.025
            }
          }
        ]
        boundingObject USE shape_wheel
        physics DEF wheel_physics Physics {
        }
      }
    }
    DEF wheel_joint HingeJoint {
      jointParameters HingeJointParameters {
        anchor -1.235 0.025 -1.28
      }
      device [
        PositionSensor {
          name "rightEncoder"
        }
        RotationalMotor {
          name "motor_2"
        }
      ]
      endPoint Solid {
        translation -1.235 0.025 -1.28
        rotation -5.497512949540586e-16 -2.670220575491141e-15 1 1.5699999999999636
        children [
          DEF shape_wheel Shape {
            appearance PBRAppearance {
              baseColor 0 0 1
              roughness 1
              metalness 0
            }
            geometry Cylinder {
              height 0.01
              radius 0.025
            }
          }
        ]
        name "solid(1)"
        boundingObject USE shape_wheel
        physics USE wheel_physics
      }
    }
    DEF eye_solid Solid {
      translation -1.265 0.07 -1.235
      children [
        Shape {
          appearance PBRAppearance {
            baseColor 0 0 1
            roughness 1
            metalness 0
          }
          geometry Box {
            size 0.005 0.005 0.005
          }
        }
      ]
      name "eye_left"
    }
    DEF eye_solid Solid {
      translation -1.295 0.07 -1.235
      children [
        Shape {
          appearance PBRAppearance {
            baseColor 0 0 1
            roughness 1
            metalness 0
          }
          geometry Box {
            size 0.005 0.005 0.005
          }
        }
      ]
      name "eye_right"
    }
    DEF Gps GPS {
      translation -1.28 0.105 -1.28
      children [
        Shape {
          appearance PBRAppearance {
          }
          geometry Box {
            size 0.01 0.01 0.01
          }
        }
      ]
    }
    DEF Imu InertialUnit {
      translation -1.28 0.105 -1.28
      children [
        Shape {
          appearance PBRAppearance {
          }
          geometry Box {
            size 0.01 0.01 0.01
          }
        }
      ]
    }
    Receiver {
      channel 1
    }
    Emitter {
      channel 2
    }
    Accelerometer {
      translation 0 -0.025 0
      name "accel"
    }
    Gyro {
    }
  ]
  boundingObject USE BodyShapeWithTransform
  physics Physics {
    density -1
    mass 1
  }
  controller "LQR"
}
